Workbook
Name aide: 'Racco D2'!$AK$4:$AK$51
Name arbre: 'Racco D2'!$B$4:$F$51
Name bloc: 'Racco D2'!$H$12:$AI$25
Name btnAujourdhui: 'Racco D2'!$AD$27:$AI$27
Name btnVue: 'Racco D2'!$AD$12:$AI$12
Name codeAPE: 'Calcul'!$B$329:$B$329
Name codeDZI: 'Calcul'!$B$637:$B$637
Name codeLVE: 'Calcul'!$B$943:$B$943
Name codeRTY: 'Calcul'!$B$790:$B$790
Name comlab: 'Calcul'!$B$82:$B$82
Name cour: 'Calcul'!$B$51:$B$51
Name cp_APE: 'Racco D2'!$T$19:$U$19
Name cp_Comlab: 'Racco D2'!$AH$16:$AI$16
Name cp_D30: 'Racco D2'!$Y$28:$Z$28
Name cp_D65: 'Racco D2'!$AH$28:$AI$28
Name cp_DZI: 'Racco D2'!$AH$19:$AI$19
Name cp_I30: 'Racco D2'!$T$13:$U$13
Name cp_I65: 'Racco D2'!$AH$13:$AI$13
Name cp_LVE: 'Racco D2'!$AH$21:$AI$21
Name cp_RTY: 'Racco D2'!$T$21:$U$21
Name date30: 'Calcul'!$C$945:$C$945
Name date65: 'Calcul'!$C$946:$C$946
Name dateDepart: 'Racco D2'!$H$29:$Q$29
Name etapeChoisie: 'Racco D2'!$AA$12:$AA$12
Name frise: 'Racco D2'!$H$13:$AI$14
Name noeuds: 'Calcul'!$A$2:$N$39
Name sel: 'Calcul'!$B$52:$B$52
Name selMemo: 'Calcul'!$B$54:$B$54
Name taches: 'Calcul'!$A$43:$R$49
Name vue: 'Calcul'!$B$53:$B$53

Sheet Racco D2
B1: Racco D2
B3: TÂCHES | E3: =COUNTIF(Calcul!$K$43:$K$49,TRUE)&" / 7" -> 0 | H3: DOSSIER
C4: FALSE | D4: 1 | E4: Réception dossier | F4: ● | H4: N° POI anticipation | O4: N° POI Racco D2 | V4: Nombre d'EL | AC4: Permis de construire | AK4: t1
C5: FALSE | E5: Demande de raccordement reçue | AK5: t1a
C6: FALSE | E6: Plans de l'immeuble reçus | H6: Adresse | V6: Cabinet conseil | AC6: DLPI | AK6: t1b
C7: FALSE | E7: Permis de construire joint | AK7: t1c
C8: FALSE | E8: Coordonnées du cabinet conseil | H8: IMB | AK8: t1d
C9: FALSE | D9: 2 | E9: Conformité | F9: ● | AK9: t2
C10: FALSE | E10: 2a Conforme | AK10: t2a
C11: FALSE | E11: Plans vérifiés | AK11: t2a1
C12: FALSE | E12: Nombre d'EL cohérent avec les plans | H12: SITUATION | O12: =IF(Calcul!$B$51=0,"Dossier terminé","Étape "&Calcul!$B$51&" en cours") -> 0 | X12: Étape | AK12: t2a2
C13: FALSE | E13: Adresse et IMB contrôlés | H13: 1 | L13: 2 | P13: 3 | T13: 4 | X13: 5 | AB13: 6 | AF13: 7 | AK13: t2a3
E14: ou | H14: Réception dossier | L14: Conformité | P14: Étude technique | T14: Planification | X14: Travaux | AB14: Recette | AF14: Mise en service | AK14: ou
C15: FALSE | E15: 2b Non conforme | H15: =Calcul!$B$52&" · "&INDEX(Calcul!$C$43:$C$49,Calcul!$B$52) -> 0 | AB15: =INDEX(Calcul!$M$43:$M$49,Calcul!$B$52) -> 0 | AK15: t2b
C16: FALSE | E16: Anomalies notifiées au cabinet conseil | H16: Statut | N16: =INDEX(Calcul!$N$43:$N$49,Calcul!$B$52) -> 0 | AK16: t2b1
C17: FALSE | E17: Compléments demandés | H17: Décision | N17: =INDEX(Calcul!$O$43:$O$49,Calcul!$B$52) -> 0 | AK17: t2b2
C18: FALSE | D18: 3 | E18: Étude technique | F18: ● | H18: Action suivante | N18: =INDEX(Calcul!$P$43:$P$49,Calcul!$B$52) -> 0 | AK18: t3
C19: FALSE | E19: Point de branchement (PBO) identifié | AK19: t3a
C20: FALSE | E20: Cheminement du câble validé | AK20: t3b
C21: FALSE | E21: Devis de raccordement envoyé | AK21: t3c
C22: FALSE | E22: Commande reçue | H22: Responsable | N22: =INDEX(Calcul!$Q$43:$Q$49,Calcul!$B$52) -> 0 | AK22: t3d
C23: FALSE | D23: 4 | E23: Planification | F23: ● | H23: Délai | N23: =IF('Racco D2'!$AC$7="","DLPI non renseignée",IF('Racco D2'!$AC$7-TODAY()>0,"J-"&('Racco D2'!$AC$7-TODAY())&" avant la DLPI",IF('Racco D2'!$AC$7-TODAY()=0,"DLPI aujourd'hui","DLPI dépassée de "&(TODAY()-'Racco D2'!$AC$7)&" j"))) -> 0 | AK23: t4
C24: FALSE | E24: Date d'intervention fixée | H24: =IF(OR(Calcul!$B$51=Calcul!$B$52,Calcul!$B$51=0),"Touche une étape de la frise ou le nom d'une grande tâche pour voir sa situation.","Étape en cours : "&Calcul!$B$51&" · "&INDEX(Calcul!$C$43:$C$49,Calcul!$B$51)) -> 0 | AK24: t4a
C25: FALSE | E25: Technicien affecté | AK25: t4b
C26: FALSE | E26: Syndic ou gestionnaire prévenu | AK26: t4c
C27: FALSE | D27: 5 | E27: Travaux | F27: ● | H27: DATES | AK27: t5
C28: FALSE | E28: Câblage de la colonne montante | H28: Date de départ | R28: + 30 JOURS | Y28: ⧉ | AA28: + 65 JOURS | AH28: ⧉ | AK28: t5a
C29: FALSE | E29: Pose des prises (PTO) dans les logements | R29: =IF(Calcul!$C$945="","—",Calcul!$D$945&" "&Calcul!$C$945) -> 0 | AA29: =IF(Calcul!$C$946="","—",Calcul!$D$946&" "&Calcul!$C$946) -> 0 | AK29: t5b
C30: FALSE | E30: Raccordement au point de branchement | H30: =IF(ISNUMBER('Racco D2'!$H$29),"Départ · "&CHOOSE(WEEKDAY('Racco D2'!$H$29),"dimanche","lundi","mardi","mercredi","jeudi","vendredi","samedi"),"") -> 0 | R30: =Calcul!$E$945 -> 0 | AA30: =Calcul!$E$946 -> 0 | AK30: t5c
C31: FALSE | E31: Photos d'intervention reçues | AK31: t5d
C32: FALSE | D32: 6 | E32: Recette | F32: ● | AK32: t6
C33: FALSE | E33: 6a Recette conforme | H33: INFO | AK33: t6a
C34: FALSE | E34: Mesures optiques dans les tolérances | H34: + 30 JOURS | T34: ⧉ | V34: + 65 JOURS | AH34: ⧉ | AK34: t6a1
C35: FALSE | E35: PV de recette signé | H35: =IF(Calcul!$C$945="","—",Calcul!$D$945&" "&Calcul!$C$945) -> 0 | R35: =Calcul!$E$945 -> 0 | V35: =IF(Calcul!$C$946="","—",Calcul!$D$946&" "&Calcul!$C$946) -> 0 | AF35: =Calcul!$E$946 -> 0 | AK35: t6a2
E36: ou | AK36: ou
C37: FALSE | E37: 6b Recette avec réserves | H37: CODE COMLAB | AH37: ⧉ | AK37: t6b
C38: FALSE | E38: Réserves notifiées au sous-traitant | H38: =MID(Calcul!$B$82,1,5)&" "&MID(Calcul!$B$82,6,5)&" "&MID(Calcul!$B$82,11,5)&" "&MID(Calcul!$B$82,16,5)&" "&MID(Calcul!$B$82,21,5) -> 0 | AK38: t6b1
C39: FALSE | E39: Reprise planifiée | AK39: t6b2
C40: FALSE | D40: 7 | E40: Mise en service | F40: ● | H40: APE | K40: =MID(Calcul!$B$329,1,5)&" "&MID(Calcul!$B$329,6,5)&" "&MID(Calcul!$B$329,11,5) -> 0 | T40: ⧉ | V40: DZI | Y40: =MID(Calcul!$B$637,1,5)&" "&MID(Calcul!$B$637,6,5)&" "&MID(Calcul!$B$637,11,5)&" "&MID(Calcul!$B$637,16,5) -> 0 | AH40: ⧉ | AK40: t7
C41: FALSE | E41: Dossier de récolement transmis | AK41: t7a
...

Sheet Calcul
A1: id | B1: libellé | C1: niveau | D1: coché | E1: effectif | F1: valide | G1: fermé | H1: parent | I1: mode | J1: index | K1: ligne | L1: verrou | M1: tag | N1: court
A2: t1 | B2: Réception dossier | C2: 1 | D2: =IF(ISLOGICAL('Racco D2'!$C$4),'Racco D2'!$C$4,FALSE) -> 0 | E2: =D2 -> 0 | F2: =OR(E2,AND(Calcul!$F$3,Calcul!$F$4,Calcul!$F$5,Calcul!$F$6)) -> 0 | G2: FALSE | I2: tout | J2: 0 | K2: 4 | L2: =Calcul!$I$43 -> 0 | M2: =Calcul!$L$43 -> 0
A3: t1a | B3: Demande de raccordement reçue | C3: 2 | D3: =IF(ISLOGICAL('Racco D2'!$C$5),'Racco D2'!$C$5,FALSE) -> 0 | E3: =OR(D3,Calcul!$E$2) -> 0 | F3: =E3 -> 0 | G3: FALSE | H3: t1 | J3: 0 | K3: 5 | L3: =Calcul!$I$43 -> 0 | M3: ="" -> 0
A4: t1b | B4: Plans de l'immeuble reçus | C4: 2 | D4: =IF(ISLOGICAL('Racco D2'!$C$6),'Racco D2'!$C$6,FALSE) -> 0 | E4: =OR(D4,Calcul!$E$2) -> 0 | F4: =E4 -> 0 | G4: FALSE | H4: t1 | J4: 1 | K4: 6 | L4: =Calcul!$I$43 -> 0 | M4: ="" -> 0
A5: t1c | B5: Permis de construire joint | C5: 2 | D5: =IF(ISLOGICAL('Racco D2'!$C$7),'Racco D2'!$C$7,FALSE) -> 0 | E5: =OR(D5,Calcul!$E$2) -> 0 | F5: =E5 -> 0 | G5: FALSE | H5: t1 | J5: 2 | K5: 7 | L5: =Calcul!$I$43 -> 0 | M5: ="" -> 0
A6: t1d | B6: Coordonnées du cabinet conseil | C6: 2 | D6: =IF(ISLOGICAL('Racco D2'!$C$8),'Racco D2'!$C$8,FALSE) -> 0 | E6: =OR(D6,Calcul!$E$2) -> 0 | F6: =E6 -> 0 | G6: FALSE | H6: t1 | J6: 3 | K6: 8 | L6: =Calcul!$I$43 -> 0 | M6: ="" -> 0
A7: t2 | B7: Conformité | C7: 1 | D7: =IF(ISLOGICAL('Racco D2'!$C$9),'Racco D2'!$C$9,FALSE) -> 0 | E7: =D7 -> 0 | F7: =OR(E7,OR(Calcul!$F$8,Calcul!$F$12)) -> 0 | G7: FALSE | I7: un | J7: 1 | K7: 9 | L7: =Calcul!$I$44 -> 0 | M7: =Calcul!$L$44 -> 0
A8: t2a | B8: 2a Conforme | C8: 2 | D8: =IF(ISLOGICAL('Racco D2'!$C$10),'Racco D2'!$C$10,FALSE) -> 0 | E8: =D8 -> 0 | F8: =OR(E8,AND(Calcul!$F$9,Calcul!$F$10,Calcul!$F$11)) -> 0 | G8: FALSE | H8: t2 | I8: tout | J8: 0 | K8: 10 | L8: =Calcul!$I$44 -> 0 | M8: ="" -> 0 | N8: Conforme
A9: t2a1 | B9: Plans vérifiés | C9: 3 | D9: =IF(ISLOGICAL('Racco D2'!$C$11),'Racco D2'!$C$11,FALSE) -> 0 | E9: =OR(D9,Calcul!$E$8) -> 0 | F9: =E9 -> 0 | G9: FALSE | H9: t2a | J9: 0 | K9: 11 | L9: =Calcul!$I$44 -> 0 | M9: ="" -> 0
A10: t2a2 | B10: Nombre d'EL cohérent avec les plans | C10: 3 | D10: =IF(ISLOGICAL('Racco D2'!$C$12),'Racco D2'!$C$12,FALSE) -> 0 | E10: =OR(D10,Calcul!$E$8) -> 0 | F10: =E10 -> 0 | G10: FALSE | H10: t2a | J10: 1 | K10: 12 | L10: =Calcul!$I$44 -> 0 | M10: ="" -> 0
A11: t2a3 | B11: Adresse et IMB contrôlés | C11: 3 | D11: =IF(ISLOGICAL('Racco D2'!$C$13),'Racco D2'!$C$13,FALSE) -> 0 | E11: =OR(D11,Calcul!$E$8) -> 0 | F11: =E11 -> 0 | G11: FALSE | H11: t2a | J11: 2 | K11: 13 | L11: =Calcul!$I$44 -> 0 | M11: ="" -> 0
A12: t2b | B12: 2b Non conforme | C12: 2 | D12: =IF(ISLOGICAL('Racco D2'!$C$15),'Racco D2'!$C$15,FALSE) -> 0 | E12: =D12 -> 0 | F12: =OR(E12,AND(Calcul!$F$13,Calcul!$F$14)) -> 0 | G12: FALSE | H12: t2 | I12: tout | J12: 1 | K12: 15 | L12: =Calcul!$I$44 -> 0 | M12: ="" -> 0 | N12: Non conforme
A13: t2b1 | B13: Anomalies notifiées au cabinet conseil | C13: 3 | D13: =IF(ISLOGICAL('Racco D2'!$C$16),'Racco D2'!$C$16,FALSE) -> 0 | E13: =OR(D13,Calcul!$E$12) -> 0 | F13: =E13 -> 0 | G13: FALSE | H13: t2b | J13: 0 | K13: 16 | L13: =Calcul!$I$44 -> 0 | M13: ="" -> 0
A14: t2b2 | B14: Compléments demandés | C14: 3 | D14: =IF(ISLOGICAL('Racco D2'!$C$17),'Racco D2'!$C$17,FALSE) -> 0 | E14: =OR(D14,Calcul!$E$12) -> 0 | F14: =E14 -> 0 | G14: FALSE | H14: t2b | J14: 1 | K14: 17 | L14: =Calcul!$I$44 -> 0 | M14: ="" -> 0
A15: t3 | B15: Étude technique | C15: 1 | D15: =IF(ISLOGICAL('Racco D2'!$C$18),'Racco D2'!$C$18,FALSE) -> 0 | E15: =D15 -> 0 | F15: =OR(E15,AND(Calcul!$F$16,Calcul!$F$17,Calcul!$F$18,Calcul!$F$19)) -> 0 | G15: FALSE | I15: tout | J15: 2 | K15: 18 | L15: =Calcul!$I$45 -> 0 | M15: =Calcul!$L$45 -> 0
A16: t3a | B16: Point de branchement (PBO) identifié | C16: 2 | D16: =IF(ISLOGICAL('Racco D2'!$C$19),'Racco D2'!$C$19,FALSE) -> 0 | E16: =OR(D16,Calcul!$E$15) -> 0 | F16: =E16 -> 0 | G16: FALSE | H16: t3 | J16: 0 | K16: 19 | L16: =Calcul!$I$45 -> 0 | M16: ="" -> 0
A17: t3b | B17: Cheminement du câble validé | C17: 2 | D17: =IF(ISLOGICAL('Racco D2'!$C$20),'Racco D2'!$C$20,FALSE) -> 0 | E17: =OR(D17,Calcul!$E$15) -> 0 | F17: =E17 -> 0 | G17: FALSE | H17: t3 | J17: 1 | K17: 20 | L17: =Calcul!$I$45 -> 0 | M17: ="" -> 0
A18: t3c | B18: Devis de raccordement envoyé | C18: 2 | D18: =IF(ISLOGICAL('Racco D2'!$C$21),'Racco D2'!$C$21,FALSE) -> 0 | E18: =OR(D18,Calcul!$E$15) -> 0 | F18: =E18 -> 0 | G18: FALSE | H18: t3 | J18: 2 | K18: 21 | L18: =Calcul!$I$45 -> 0 | M18: ="" -> 0
A19: t3d | B19: Commande reçue | C19: 2 | D19: =IF(ISLOGICAL('Racco D2'!$C$22),'Racco D2'!$C$22,FALSE) -> 0 | E19: =OR(D19,Calcul!$E$15) -> 0 | F19: =E19 -> 0 | G19: FALSE | H19: t3 | J19: 3 | K19: 22 | L19: =Calcul!$I$45 -> 0 | M19: ="" -> 0
A20: t4 | B20: Planification | C20: 1 | D20: =IF(ISLOGICAL('Racco D2'!$C$23),'Racco D2'!$C$23,FALSE) -> 0 | E20: =D20 -> 0 | F20: =OR(E20,AND(Calcul!$F$21,Calcul!$F$22,Calcul!$F$23)) -> 0 | G20: FALSE | I20: tout | J20: 3 | K20: 23 | L20: =Calcul!$I$46 -> 0 | M20: =Calcul!$L$46 -> 0
A21: t4a | B21: Date d'intervention fixée | C21: 2 | D21: =IF(ISLOGICAL('Racco D2'!$C$24),'Racco D2'!$C$24,FALSE) -> 0 | E21: =OR(D21,Calcul!$E$20) -> 0 | F21: =E21 -> 0 | G21: FALSE | H21: t4 | J21: 0 | K21: 24 | L21: =Calcul!$I$46 -> 0 | M21: ="" -> 0
A22: t4b | B22: Technicien affecté | C22: 2 | D22: =IF(ISLOGICAL('Racco D2'!$C$25),'Racco D2'!$C$25,FALSE) -> 0 | E22: =OR(D22,Calcul!$E$20) -> 0 | F22: =E22 -> 0 | G22: FALSE | H22: t4 | J22: 1 | K22: 25 | L22: =Calcul!$I$46 -> 0 | M22: ="" -> 0
A23: t4c | B23: Syndic ou gestionnaire prévenu | C23: 2 | D23: =IF(ISLOGICAL('Racco D2'!$C$26),'Racco D2'!$C$26,FALSE) -> 0 | E23: =OR(D23,Calcul!$E$20) -> 0 | F23: =E23 -> 0 | G23: FALSE | H23: t4 | J23: 2 | K23: 26 | L23: =Calcul!$I$46 -> 0 | M23: ="" -> 0
A24: t5 | B24: Travaux | C24: 1 | D24: =IF(ISLOGICAL('Racco D2'!$C$27),'Racco D2'!$C$27,FALSE) -> 0 | E24: =D24 -> 0 | F24: =OR(E24,AND(Calcul!$F$25,Calcul!$F$26,Calcul!$F$27,Calcul!$F$28)) -> 0 | G24: FALSE | I24: tout | J24: 4 | K24: 27 | L24: =Calcul!$I$47 -> 0 | M24: =Calcul!$L$47 -> 0
A25: t5a | B25: Câblage de la colonne montante | C25: 2 | D25: =IF(ISLOGICAL('Racco D2'!$C$28),'Racco D2'!$C$28,FALSE) -> 0 | E25: =OR(D25,Calcul!$E$24) -> 0 | F25: =E25 -> 0 | G25: FALSE | H25: t5 | J25: 0 | K25: 28 | L25: =Calcul!$I$47 -> 0 | M25: ="" -> 0
A26: t5b | B26: Pose des prises (PTO) dans les logements | C26: 2 | D26: =IF(ISLOGICAL('Racco D2'!$C$29),'Racco D2'!$C$29,FALSE) -> 0 | E26: =OR(D26,Calcul!$E$24) -> 0 | F26: =E26 -> 0 | G26: FALSE | H26: t5 | J26: 1 | K26: 29 | L26: =Calcul!$I$47 -> 0 | M26: ="" -> 0
A27: t5c | B27: Raccordement au point de branchement | C27: 2 | D27: =IF(ISLOGICAL('Racco D2'!$C$30),'Racco D2'!$C$30,FALSE) -> 0 | E27: =OR(D27,Calcul!$E$24) -> 0 | F27: =E27 -> 0 | G27: FALSE | H27: t5 | J27: 2 | K27: 30 | L27: =Calcul!$I$47 -> 0 | M27: ="" -> 0
A28: t5d | B28: Photos d'intervention reçues | C28: 2 | D28: =IF(ISLOGICAL('Racco D2'!$C$31),'Racco D2'!$C$31,FALSE) -> 0 | E28: =OR(D28,Calcul!$E$24) -> 0 | F28: =E28 -> 0 | G28: FALSE | H28: t5 | J28: 3 | K28: 31 | L28: =Calcul!$I$47 -> 0 | M28: ="" -> 0
A29: t6 | B29: Recette | C29: 1 | D29: =IF(ISLOGICAL('Racco D2'!$C$32),'Racco D2'!$C$32,FALSE) -> 0 | E29: =D29 -> 0 | F29: =OR(E29,OR(Calcul!$F$30,Calcul!$F$33)) -> 0 | G29: FALSE | I29: un | J29: 5 | K29: 32 | L29: =Calcul!$I$48 -> 0 | M29: =Calcul!$L$48 -> 0
A30: t6a | B30: 6a Recette conforme | C30: 2 | D30: =IF(ISLOGICAL('Racco D2'!$C$33),'Racco D2'!$C$33,FALSE) -> 0 | E30: =D30 -> 0 | F30: =OR(E30,AND(Calcul!$F$31,Calcul!$F$32)) -> 0 | G30: FALSE | H30: t6 | I30: tout | J30: 0 | K30: 33 | L30: =Calcul!$I$48 -> 0 | M30: ="" -> 0 | N30: Recette conforme
A31: t6a1 | B31: Mesures optiques dans les tolérances | C31: 3 | D31: =IF(ISLOGICAL('Racco D2'!$C$34),'Racco D2'!$C$34,FALSE) -> 0 | E31: =OR(D31,Calcul!$E$30) -> 0 | F31: =E31 -> 0 | G31: FALSE | H31: t6a | J31: 0 | K31: 34 | L31: =Calcul!$I$48 -> 0 | M31: ="" -> 0
A32: t6a2 | B32: PV de recette signé | C32: 3 | D32: =IF(ISLOGICAL('Racco D2'!$C$35),'Racco D2'!$C$35,FALSE) -> 0 | E32: =OR(D32,Calcul!$E$30) -> 0 | F32: =E32 -> 0 | G32: FALSE | H32: t6a | J32: 1 | K32: 35 | L32: =Calcul!$I$48 -> 0 | M32: ="" -> 0
A33: t6b | B33: 6b Recette avec réserves | C33: 2 | D33: =IF(ISLOGICAL('Racco D2'!$C$37),'Racco D2'!$C$37,FALSE) -> 0 | E33: =D33 -> 0 | F33: =OR(E33,AND(Calcul!$F$34,Calcul!$F$35)) -> 0 | G33: FALSE | H33: t6 | I33: tout | J33: 1 | K33: 37 | L33: =Calcul!$I$48 -> 0 | M33: ="" -> 0 | N33: Réserves
A34: t6b1 | B34: Réserves notifiées au sous-traitant | C34: 3 | D34: =IF(ISLOGICAL('Racco D2'!$C$38),'Racco D2'!$C$38,FALSE) -> 0 | E34: =OR(D34,Calcul!$E$33) -> 0 | F34: =E34 -> 0 | G34: FALSE | H34: t6b | J34: 0 | K34: 38 | L34: =Calcul!$I$48 -> 0 | M34: ="" -> 0
A35: t6b2 | B35: Reprise planifiée | C35: 3 | D35: =IF(ISLOGICAL('Racco D2'!$C$39),'Racco D2'!$C$39,FALSE) -> 0 | E35: =OR(D35,Calcul!$E$33) -> 0 | F35: =E35 -> 0 | G35: FALSE | H35: t6b | J35: 1 | K35: 39 | L35: =Calcul!$I$48 -> 0 | M35: ="" -> 0
A36: t7 | B36: Mise en service | C36: 1 | D36: =IF(ISLOGICAL('Racco D2'!$C$40),'Racco D2'!$C$40,FALSE) -> 0 | E36: =D36 -> 0 | F36: =OR(E36,AND(Calcul!$F$37,Calcul!$F$38,Calcul!$F$39)) -> 0 | G36: FALSE | I36: tout | J36: 6 | K36: 40 | L36: =Calcul!$I$49 -> 0 | M36: =Calcul!$L$49 -> 0
A37: t7a | B37: Dossier de récolement transmis | C37: 2 | D37: =IF(ISLOGICAL('Racco D2'!$C$41),'Racco D2'!$C$41,FALSE) -> 0 | E37: =OR(D37,Calcul!$E$36) -> 0 | F37: =E37 -> 0 | G37: FALSE | H37: t7 | J37: 0 | K37: 41 | L37: =Calcul!$I$49 -> 0 | M37: ="" -> 0
A38: t7b | B38: IMB passés actifs dans le SI | C38: 2 | D38: =IF(ISLOGICAL('Racco D2'!$C$42),'Racco D2'!$C$42,FALSE) -> 0 | E38: =OR(D38,Calcul!$E$36) -> 0 | F38: =E38 -> 0 | G38: FALSE | H38: t7 | J38: 1 | K38: 42 | L38: =Calcul!$I$49 -> 0 | M38: ="" -> 0
A39: t7c | B39: Dossier clôturé | C39: 2 | D39: =IF(ISLOGICAL('Racco D2'!$C$43),'Racco D2'!$C$43,FALSE) -> 0 | E39: =OR(D39,Calcul!$E$36) -> 0 | F39: =E39 -> 0 | G39: FALSE | H39: t7 | J39: 2 | K39: 43 | L39: =Calcul!$I$49 -> 0 | M39: ="" -> 0
A42: n° | B42: id | C42: libellé | D42: valide | E42: branche A | F42: branche B | G42: en A | H42: en B | I42: verrou | J42: ko | K42: acquise | L42: tag | M42: texte | N42: statut | O42: décision | P42: action | Q42: responsable | R42: lettre
...

Sheet Paramètres
A1: Paramètres | D1: Alphabet base 32 des codes
A2: Délai date 1 (jours) | B2: 30 | D2: 0123456789ABCDEFGHJKMNPQRSTVWXYZ
A3: Délai date 2 (jours) | B3: 65
A5: Jours fériés (France)
B6: 45292
B7: 45383
B8: 45413
B9: 45420
B10: 45421
B11: 45432
B12: 45487
B13: 45519
B14: 45597
B15: 45607
B16: 45651
B17: 45658
... B247: 53321
